#VRML_SIM R2020b utf8
# license: Apache License 2.0
# license url: http://www.apache.org/licenses/LICENSE-2.0
# This is a proto file for Webots for the KukaKr3r540
# Extracted from: model.urdf

PROTO KukaKr3r540 [
  field  SFVec3f     translation     0 0 0
  field  SFRotation  rotation     1 0 0 -1.5708
  field  SFString    controller      "void" # Is `Robot.controller`.
  field  MFString    controllerArgs  []     # Is `Robot.controllerArgs`.
  field  SFString    customData      ""     # Is `Robot.customData`.
  field  SFBool      supervisor      FALSE  # Is `Robot.supervisor`.
  field  SFBool      synchronization TRUE   # Is `Robot.synchronization`.
  field  SFBool      selfCollision   FALSE  # Is `Robot.selfCollision`.
  field  SFBool      staticBase      TRUE  # Defines if the robot base should be pinned to the static environment.
  field  MFNode      toolSlot        []     # Extend the robot with new nodes at the end of the arm.
]
{
  Robot {
    translation IS translation
    rotation IS rotation
    controller IS controller
    controllerArgs IS controllerArgs
    customData IS customData
    supervisor IS supervisor
    synchronization IS synchronization
    selfCollision IS selfCollision
    children [
      base_linkMesh {
      }
      HingeJoint {
        jointParameters HingeJointParameters {
          axis 0.000000 0.000000 -1.000000
          anchor 0.000000 0.000000 0.345000
          dampingConstant 0.0
          staticFriction 0.0
        }
        device [
          RotationalMotor {
            name "joint_a1"
            maxVelocity 9.25024503557
            minPosition -2.96705972839
            maxPosition 2.96705972839
          }
          PositionSensor {
            name "joint_a1_sensor"
          }
        ]
        endPoint Solid {
          translation 0.000000 0.000000 0.345000
          rotation 0.000000 1.000000 0.000000 0.000000
          children [
            link_1Mesh {
            }
            HingeJoint {
              jointParameters HingeJointParameters {
                axis 0.000000 1.000000 0.000000
                anchor 0.020000 0.000000 0.000000
                dampingConstant 0.0
                staticFriction 0.0
              }
              device [
                RotationalMotor {
                  name "joint_a2"
                  maxVelocity 9.23279174305
                  minPosition -2.96705972839
                  maxPosition 0.872664625997
                }
                PositionSensor {
                  name "joint_a2_sensor"
                }
              ]
              endPoint Solid {
                translation 0.020000 0.000000 0.000000
                rotation 0.000000 1.000000 0.000000 0.000000
                children [
                  link_2Mesh {
                  }
                  HingeJoint {
                    jointParameters HingeJointParameters {
                      axis 0.000000 1.000000 0.000000
                      anchor 0.260000 0.000000 0.000000
                      dampingConstant 0.0
                      staticFriction 0.0
                    }
                    device [
                      RotationalMotor {
                        name "joint_a3"
                        maxVelocity 9.38987137573
                        minPosition -1.91986217719
                        maxPosition 2.70526034059
                      }
                      PositionSensor {
                        name "joint_a3_sensor"
                      }
                    ]
                    endPoint Solid {
                      translation 0.260000 0.000000 0.000000
                      rotation 0.000000 1.000000 0.000000 0.000000
                      children [
                        link_3Mesh {
                        }
                        HingeJoint {
                          jointParameters HingeJointParameters {
                            axis -1.000000 0.000000 0.000000
                            anchor 0.000000 0.000000 0.020000
                            dampingConstant 0.0
                            staticFriction 0.0
                          }
                          device [
                            RotationalMotor {
                              name "joint_a4"
                              maxVelocity 10.471975512
                              minPosition -3.05432619099
                              maxPosition 3.05432619099
                            }
                            PositionSensor {
                              name "joint_a4_sensor"
                            }
                          ]
                          endPoint Solid {
                            translation 0.000000 0.000000 0.020000
                            rotation 0.000000 1.000000 0.000000 0.000000
                            children [
                              link_4Mesh {
                              }
                              HingeJoint {
                                jointParameters HingeJointParameters {
                                  axis 0.000000 1.000000 0.000000
                                  anchor 0.260000 0.000000 0.000000
                                  dampingConstant 0.0
                                  staticFriction 0.0
                                }
                                device [
                                  RotationalMotor {
                                    name "joint_a5"
                                    maxVelocity 10.471975512
                                    minPosition -2.09439510239
                                    maxPosition 2.09439510239
                                  }
                                  PositionSensor {
                                    name "joint_a5_sensor"
                                  }
                                ]
                                endPoint Solid {
                                  translation 0.260000 0.000000 0.000000
                                  rotation 0.000000 1.000000 0.000000 0.000000
                                  children [
                                    link_5Mesh {
                                    }
                                    HingeJoint {
                                      jointParameters HingeJointParameters {
                                        axis -1.000000 0.000000 0.000000
                                        anchor 0.075000 0.000000 0.000000
                                        dampingConstant 0.0
                                        staticFriction 0.0
                                      }
                                      device [
                                        RotationalMotor {
                                          name "joint_a6"
                                          maxVelocity 13.962634016
                                          minPosition -6.10865238198
                                          maxPosition 6.10865238198
                                        }
                                        PositionSensor {
                                          name "joint_a6_sensor"
                                        }
                                      ]
                                      endPoint Solid {
                                        translation 0.075000 0.000000 0.000000
                                        rotation 0.000000 1.000000 0.000000 0.000000
                                        children [
                                          link_6Mesh {
                                          }
                                          Solid {
                                            translation 0.000000 0.000000 0.000000
                                            rotation 0.000000 1.000000 0.000000 1.570796
                                            children [
                                              Group {
                                                children IS toolSlot
                                              }
                                            ]
                                            name "tool0"
                                          }
                                        ]
                                        name "link_6"
                                        boundingObject Transform {
                                          translation -0.008000 -0.000007 0.000000
                                          children [
                                            Box {
                                              size 0.016000 0.053985 0.053981
                                            }
                                          ]
                                        }
                                        physics Physics {
                                          density -1
                                          mass 1.000000
                                          centerOfMass [ 0.000000 0.000000 0.000000 ]
                                        }
                                      }
                                    }
                                  ]
                                  name "link_5"
                                  boundingObject Transform {
                                    translation 0.005770 -0.001000 0.000000
                                    children [
                                      Box {
                                        size 0.116461 0.090000 0.081000
                                      }
                                    ]
                                  }
                                  physics Physics {
                                    density -1
                                    mass 1.000000
                                    centerOfMass [ 0.000000 0.000000 0.000000 ]
                                  }
                                }
                              }
                            ]
                            name "link_4"
                            boundingObject Transform {
                              translation 0.205661 0.003471 -0.000010
                              children [
                                Box {
                                  size 0.184921 0.135822 0.100315
                                }
                              ]
                            }
                            physics Physics {
                              density -1
                              mass 1.000000
                              centerOfMass [ 0.000000 0.000000 0.000000 ]
                            }
                          }
                        }
                      ]
                      name "link_3"
                      boundingObject Transform {
                        translation 0.030248 -0.000400 0.004391
                        children [
                          Box {
                            size 0.185906 0.119200 0.134217
                          }
                        ]
                      }
                      physics Physics {
                        density -1
                        mass 1.000000
                        centerOfMass [ 0.000000 0.000000 0.000000 ]
                      }
                    }
                  }
                ]
                name "link_2"
                boundingObject Transform {
                  translation 0.125664 0.001507 0.011208
                  children [
                    Box {
                      size 0.359165 0.198986 0.130194
                    }
                  ]
                }
                physics Physics {
                  density -1
                  mass 1.000000
                  centerOfMass [ 0.000000 0.000000 0.000000 ]
                }
              }
            }
          ]
          name "link_1"
          boundingObject Transform {
            translation 0.001508 0.001994 -0.060260
            children [
              Box {
                size 0.235041 0.204011 0.221480
              }
            ]
          }
          physics Physics {
            density -1
            mass 1.000000
            centerOfMass [ 0.000000 0.000000 0.000000 ]
          }
        }
      }
      Solid {
        translation 0.000000 0.000000 0.000000
        rotation 0.000000 1.000000 0.000000 0.000000
        name "base"
      }
    ]
    name "base_link"
    boundingObject Transform {
      translation -0.049494 0.000000 0.100000
      children [
        Box {
          size 0.285247 0.186421 0.200000
        }
      ]
    }
    %{ if fields.staticBase.value == false then }%
    physics Physics {
      density -1
      mass 1.000000
      centerOfMass [ 0.000000 0.000000 0.000000 ]
    }
    %{ end }%
  }
}
