#VRML_SIM R2020b utf8
# license: Apache License 2.0
# license url: http://www.apache.org/licenses/LICENSE-2.0
# This is a proto file for Webots for the Mirobot
# Extracted from: model.urdf

PROTO Mirobot [
  field  SFVec3f     translation     0 0 0
  field  SFRotation  rotation        1 0 0 -1.5708
  field  SFString    controller      "void" # Is `Robot.controller`.
  field  MFString    controllerArgs  []     # Is `Robot.controllerArgs`.
  field  SFString    customData      ""     # Is `Robot.customData`.
  field  SFBool      supervisor      FALSE  # Is `Robot.supervisor`.
  field  SFBool      synchronization TRUE   # Is `Robot.synchronization`.
  field  SFBool      selfCollision   FALSE  # Is `Robot.selfCollision`.
  field  SFBool      staticBase      TRUE   # Defines if the robot base should be pinned to the static environment.
  field  MFNode      toolSlot        []     # Extend the robot with new nodes at the end of the arm.
]
{
  Robot {
    translation IS translation
    rotation IS rotation
    controller IS controller
    controllerArgs IS controllerArgs
    customData IS customData
    supervisor IS supervisor
    synchronization IS synchronization
    selfCollision IS selfCollision
    children [
      Mirobot_base_linkMesh {
      }
      HingeJoint {
        jointParameters HingeJointParameters {
          axis 0.000000 0.000000 1.000000
          anchor 0.000000 0.000000 0.065406
          dampingConstant 0.0
          staticFriction 0.0
        }
        device [
          RotationalMotor {
            name "joint1"
            maxVelocity 0.514
            minPosition -1.7453
            maxPosition 2.7925
            maxTorque 200.0
          }
          PositionSensor {
            name "joint1_sensor"
          }
        ]
        endPoint Solid {
          translation 0.000000 0.000000 0.065406
          rotation 0.000000 1.000000 0.000000 0.000000
          children [
            Mirobot_Link1Mesh {
            }
            HingeJoint {
              jointParameters HingeJointParameters {
                axis -0.000011 1.000000 0.000004
                anchor 0.029687 -0.022000 0.061593
                dampingConstant 0.0
                staticFriction 0.0
              }
              device [
                RotationalMotor {
                  name "joint2"
                  maxVelocity 1.134
                  minPosition -0.5235
                  maxPosition 1.2217
                  maxTorque 200.0
                }
                PositionSensor {
                  name "joint2_sensor"
                }
              ]
              endPoint Solid {
                translation 0.029687 -0.022000 0.061593
                rotation 0.577347 0.577354 0.577350 4.188799
                children [
                  Mirobot_Link2Mesh {
                  }
                  HingeJoint {
                    jointParameters HingeJointParameters {
                      axis 0.000000 0.000000 1.000000
                      anchor 0.108000 0.000000 -0.009447
                      dampingConstant 0.0
                      staticFriction 0.0
                    }
                    device [
                      RotationalMotor {
                        name "joint3"
                        maxVelocity 0.489
                        minPosition -2.9671
                        maxPosition 1.0472
                        maxTorque 200.0
                      }
                      PositionSensor {
                        name "joint3_sensor"
                      }
                    ]
                    endPoint Solid {
                      translation 0.108000 0.000000 -0.009447
                      rotation 0.000000 1.000000 0.000000 0.000000
                      children [
                        Mirobot_Link3Mesh {
                        }
                        HingeJoint {
                          jointParameters HingeJointParameters {
                            axis 0.000000 1.000000 -0.000004
                            anchor 0.020001 0.107430 0.031439
                            dampingConstant 0.0
                            staticFriction 0.0
                          }
                          device [
                            RotationalMotor {
                              name "joint4"
                              maxVelocity 1.92
                              minPosition -6.1086
                              maxPosition 6.1086
                              maxTorque 200.0
                            }
                            PositionSensor {
                              name "joint4_sensor"
                            }
                          ]
                          endPoint Solid {
                            translation 0.020001 0.107430 0.031439
                            rotation -1.000000 0.000000 0.000000 1.570800
                            children [
                              Mirobot_Link4Mesh {
                              }
                              HingeJoint {
                                jointParameters HingeJointParameters {
                                  axis -0.000004 -1.000000 -0.000000
                                  anchor 0.000000 -0.010414 0.061550
                                  dampingConstant 0.0
                                  staticFriction 0.0
                                }
                                device [
                                  RotationalMotor {
                                    name "joint5"
                                    maxVelocity 0.576
                                    minPosition -3.5779
                                    maxPosition 0.6283
                                    maxTorque 200.0
                                  }
                                  PositionSensor {
                                    name "joint5_sensor"
                                  }
                                ]
                                endPoint Solid {
                                  translation 0.000000 -0.010414 0.061550
                                  rotation -0.577352 -0.577348 -0.577350 2.094395
                                  children [
                                    Mirobot_Link5Mesh {
                                    }
                                    HingeJoint {
                                      jointParameters HingeJointParameters {
                                        axis 0.000000 1.000000 -0.000004
                                        anchor 0.000000 -0.016280 0.010525
                                        dampingConstant 0.0
                                        staticFriction 0.0
                                      }
                                      device [
                                        RotationalMotor {
                                          name "joint6"
                                          maxVelocity 1.152
                                          minPosition -6.2832
                                          maxPosition 6.2832
                                          maxTorque 200.0
                                        }
                                        PositionSensor {
                                          name "joint6_sensor"
                                        }
                                      ]
                                      endPoint Solid {
                                        translation 0.000000 -0.016280 0.010525
                                        rotation -1.000000 0.000000 0.000000 1.570800
                                        children [
                                          Mirobot_Link6Mesh {
                                          }
                                          Solid {
                                            translation 0 0 -0.0295
                                            rotation 0 1 0 3.14159
                                            children [
                                              Group {
                                                children IS toolSlot
                                              }
                                            ]
                                            name "tool0"
                                            boundingObject Box {
                                                   size 0.01 0.01 0.01
                                                }
                                            physics Physics {
                                              centerOfMass [ 0 0 0 ]
                                            }
                                          }
                                        ]
                                        name "Link6"
                                        boundingObject Transform {
                                          translation 0.000000 0.000000 -0.012233
                                          children [
                                            Box {
                                              size 0.022000 0.022000 0.034465
                                            }
                                          ]
                                        }
                                        physics Physics {
                                          density -1
                                          mass 0.001000
                                          centerOfMass [ 0.000000 0.000000 -0.010506 ]
                                        }
                                      }
                                    }
                                  ]
                                  name "Link5"
                                  boundingObject Transform {
                                    translation 0.000791 -0.007540 0.009239
                                    children [
                                      Box {
                                        size 0.019903 0.033480 0.024428
                                      }
                                    ]
                                  }
                                  physics Physics {
                                    density -1
                                    mass 0.001000
                                    centerOfMass [ 0.000253 -0.002013 0.010352 ]
                                  }
                                }
                              }
                            ]
                            name "Link4"
                            boundingObject Transform {
                              translation -0.000006 0.001462 0.041047
                              children [
                                Box {
                                  size 0.028194 0.043775 0.070514
                                }
                              ]
                            }
                            physics Physics {
                              density -1
                              mass 0.001000
                              centerOfMass [ -0.000008 0.004380 0.040569 ]
                            }
                          }
                        }
                      ]
                      name "Link3"
                      boundingObject Transform {
                        translation 0.008944 0.038353 0.037470
                        children [
                          Box {
                            size 0.075524 0.149730 0.074939
                          }
                        ]
                      }
                      physics Physics {
                        density -1
                        mass 0.001000
                        centerOfMass [ 0.010000 0.007140 0.037517 ]
                      }
                    }
                  }
                ]
                name "Link2"
                boundingObject Transform {
                  translation 0.053001 -0.001120 -0.006111
                  children [
                    Box {
                      size 0.143506 0.054665 0.032223
                    }
                  ]
                }
                physics Physics {
                  density -1
                  mass 0.001000
                  centerOfMass [ 0.054694 0.003638 -0.005611 ]
                }
              }
            }
          ]
          name "Link1"
          boundingObject Transform {
            translation 0.004702 0.017805 0.045482
            children [
              Box {
                size 0.108124 0.115470 0.090377
              }
            ]
          }
          physics Physics {
            density -1
            mass 0.001000
            centerOfMass [ 0.011601 0.022341 0.044136 ]
          }
        }
      }
    ]
    name "base_link"
    boundingObject Transform {
      translation 0.000000 0.000000 0.033695
      children [
        Box {
          size 0.160000 0.160000 0.067390
        }
      ]
    }
    %{ if fields.staticBase.value == false then }%
    physics Physics {
      density -1
      mass 0.010000
      centerOfMass [ 0.000726 0.000022 0.024268 ]
    }
    %{ end }%
  }
}
