#VRML_SIM R2020b utf8
# license: Apache License 2.0
# license url: http://www.apache.org/licenses/LICENSE-2.0
# This is a proto file for Webots for the KukaKr6r700sixx
# Extracted from: model.urdf

PROTO KukaKr6r700sixx [
  field  SFVec3f     translation     0 0 0
  field  SFRotation  rotation        1 0 0 -1.5708
  field  SFString    controller      "void" # Is `Robot.controller`.
  field  MFString    controllerArgs  []     # Is `Robot.controllerArgs`.
  field  SFString    customData      ""     # Is `Robot.customData`.
  field  SFBool      supervisor      FALSE  # Is `Robot.supervisor`.
  field  SFBool      synchronization TRUE   # Is `Robot.synchronization`.
  field  SFBool      selfCollision   FALSE  # Is `Robot.selfCollision`.
  field  SFBool      staticBase      TRUE   # Defines if the robot base should be pinned to the static environment.
  field  MFNode      toolSlot        []     # Extend the robot with new nodes at the end of the arm.
]
{
  Robot {
    translation IS translation
    rotation IS rotation
    controller IS controller
    controllerArgs IS controllerArgs
    customData IS customData
    supervisor IS supervisor
    synchronization IS synchronization
    selfCollision IS selfCollision
    children [
      KukaKr6r700sixx_base_link_0Mesh {
      }
      HingeJoint {
        jointParameters HingeJointParameters {
          axis 0.000000 0.000000 -1.000000
          anchor 0.000000 0.000000 0.400000
          dampingConstant 0.0
          staticFriction 0.0
        }
        device [
          RotationalMotor {
            name "joint_a1"
            maxVelocity 6.28318530718
            minPosition -2.96705972839
            maxPosition 2.96705972839
            maxTorque 10000
          }
          PositionSensor {
            name "joint_a1_sensor"
          }
        ]
        endPoint Solid {
          translation 0.000000 0.000000 0.400000
          rotation 0.000000 1.000000 0.000000 0.000000
          children [
            KukaKr6r700sixx_link_1_0Mesh {
            }
            HingeJoint {
              jointParameters HingeJointParameters {
                axis 0.000000 1.000000 0.000000
                anchor 0.025000 0.000000 0.000000
                dampingConstant 0.0
                staticFriction 0.0
              }
              device [
                RotationalMotor {
                  name "joint_a2"
                  maxVelocity 5.23598775598
                  minPosition -3.31612557879
                  maxPosition 0.785398163397
                  maxTorque 10000
                }
                PositionSensor {
                  name "joint_a2_sensor"
                }
              ]
              endPoint Solid {
                translation 0.025000 0.000000 0.000000
                rotation 0.000000 1.000000 0.000000 0.000000
                children [
                  KukaKr6r700sixx_link_2_0Mesh {
                  }
                  HingeJoint {
                    jointParameters HingeJointParameters {
                      axis 0.000000 1.000000 0.000000
                      anchor 0.315000 0.000000 0.000000
                      dampingConstant 0.0
                      staticFriction 0.0
                    }
                    device [
                      RotationalMotor {
                        name "joint_a3"
                        maxVelocity 6.28318530718
                        minPosition -2.09439510239
                        maxPosition 2.72271363311
                        maxTorque 10000
                      }
                      PositionSensor {
                        name "joint_a3_sensor"
                      }
                    ]
                    endPoint Solid {
                      translation 0.315000 0.000000 0.000000
                      rotation 0.000000 1.000000 0.000000 0.000000
                      children [
                        KukaKr6r700sixx_link_3_0Mesh {
                        }
                        HingeJoint {
                          jointParameters HingeJointParameters {
                            axis -1.000000 0.000000 0.000000
                            anchor 0.000000 0.000000 0.035000
                            dampingConstant 0.0
                            staticFriction 0.0
                          }
                          device [
                            RotationalMotor {
                              name "joint_a4"
                              maxVelocity 6.6497044501
                              minPosition -3.22885911619
                              maxPosition 3.22885911619
                              maxTorque 10000
                            }
                            PositionSensor {
                              name "joint_a4_sensor"
                            }
                          ]
                          endPoint Solid {
                            translation 0.000000 0.000000 0.035000
                            rotation 0.000000 1.000000 0.000000 0.000000
                            children [
                              KukaKr6r700sixx_link_4_0Mesh {
                              }
                              HingeJoint {
                                jointParameters HingeJointParameters {
                                  axis 0.000000 1.000000 0.000000
                                  anchor 0.365000 0.000000 0.000000
                                  dampingConstant 0.0
                                  staticFriction 0.0
                                }
                                device [
                                  RotationalMotor {
                                    name "joint_a5"
                                    maxVelocity 6.77187749774
                                    minPosition -2.09439510239
                                    maxPosition 2.09439510239
                                    maxTorque 10000
                                  }
                                  PositionSensor {
                                    name "joint_a5_sensor"
                                  }
                                ]
                                endPoint Solid {
                                  translation 0.365000 0.000000 0.000000
                                  rotation 0.000000 1.000000 0.000000 0.000000
                                  children [
                                    KukaKr6r700sixx_link_5_0Mesh {
                                    }
                                    HingeJoint {
                                      jointParameters HingeJointParameters {
                                        axis -1.000000 0.000000 0.000000
                                        anchor 0.080000 0.000000 0.000000
                                        dampingConstant 0.0
                                        staticFriction 0.0
                                      }
                                      device [
                                        RotationalMotor {
                                          name "joint_a6"
                                          maxVelocity 10.7337748998
                                          minPosition -6.10865238198
                                          maxPosition 6.10865238198
                                          maxTorque 10000
                                        }
                                        PositionSensor {
                                          name "joint_a6_sensor"
                                        }
                                      ]
                                      endPoint Solid {
                                        translation 0.080000 0.000000 0.000000
                                        rotation 0.000000 1.000000 0.000000 0.000000
                                        children [
                                          KukaKr6r700sixx_link_6_0Mesh {
                                          }
                                          Solid {
                                            translation 0.000000 0.000000 0.000000
                                            rotation 0.000000 1.000000 0.000000 1.570796
                                            children [
                                              Group {
                                                children IS toolSlot
                                              }
                                            ]
                                            name "tool0"
                                          }
                                        ]
                                        name "link_6"
                                        boundingObject Transform {
                                          translation -0.006757 0.000000 -0.000011
                                          children [
                                            Box {
                                              size 0.013500 0.039999 0.039999
                                            }
                                          ]
                                        }
                                        physics Physics {
                                          density -1
                                          mass 1.000000
                                          centerOfMass [ 0.000000 0.000000 0.000000 ]
                                        }
                                      }
                                    }
                                  ]
                                  name "link_5"
                                  boundingObject Transform {
                                    translation 0.019793 -0.000250 -0.000012
                                    children [
                                      Box {
                                        size 0.119001 0.078499 0.079404
                                      }
                                    ]
                                  }
                                  physics Physics {
                                    density -1
                                    mass 1.000000
                                    centerOfMass [ 0.000000 0.000000 0.000000 ]
                                  }
                                }
                              }
                            ]
                            name "link_4"
                            boundingObject Transform {
                              translation 0.257619 0.001921 0.008671
                              children [
                                Box {
                                  size 0.301469 0.135151 0.128817
                                }
                              ]
                            }
                            physics Physics {
                              density -1
                              mass 1.000000
                              centerOfMass [ 0.000000 0.000000 0.000000 ]
                            }
                          }
                        }
                      ]
                      name "link_3"
                      boundingObject Transform {
                        translation 0.020251 -0.000000 0.007991
                        children [
                          Box {
                            size 0.193495 0.134998 0.168994
                          }
                        ]
                      }
                      physics Physics {
                        density -1
                        mass 1.000000
                        centerOfMass [ 0.000000 0.000000 0.000000 ]
                      }
                    }
                  }
                ]
                name "link_2"
                boundingObject Transform {
                  translation 0.156563 -0.003576 -0.000113
                  children [
                    Box {
                      size 0.492693 0.250920 0.178591
                    }
                  ]
                }
                physics Physics {
                  density -1
                  mass 1.000000
                  centerOfMass [ 0.000000 0.000000 0.000000 ]
                }
              }
            }
          ]
          name "link_1"
          boundingObject Transform {
            translation 0.011589 -0.001003 -0.048342
            children [
              Box {
                size 0.242818 0.275965 0.269322
              }
            ]
          }
          physics Physics {
            density -1
            mass 1.000000
            centerOfMass [ 0.000000 0.000000 0.000000 ]
          }
        }
      }
      Solid {
        translation 0.000000 0.000000 0.000000
        rotation 0.000000 1.000000 0.000000 0.000000
        name "base"
      }
    ]
    name "base_link"
    boundingObject Transform {
      translation -0.056820 -0.000003 0.130398
      children [
        Box {
          size 0.328355 0.214739 0.260797
        }
      ]
    }
    %{ if fields.staticBase.value == false then }%
    physics Physics {
      density -1
      mass 1.000000
      centerOfMass [ 0.000000 0.000000 0.000000 ]
    }
    %{ end }%
  }
}
