#VRML_SIM R2020b utf8
# license: Apache License 2.0
# license url: http://www.apache.org/licenses/LICENSE-2.0
# This is a proto file for Webots for the KukaKr1502
# Extracted from: model.urdf

PROTO KukaKr1502 [
  field  SFVec3f     translation     0 0 0
  field  SFRotation  rotation        1 0 0 -1.5708
  field  SFString    controller      "void" # Is `Robot.controller`.
  field  MFString    controllerArgs  []     # Is `Robot.controllerArgs`.
  field  SFString    customData      ""     # Is `Robot.customData`.
  field  SFBool      supervisor      FALSE  # Is `Robot.supervisor`.
  field  SFBool      synchronization TRUE   # Is `Robot.synchronization`.
  field  SFBool      selfCollision   FALSE  # Is `Robot.selfCollision`.
  field  SFBool      staticBase      TRUE   # Defines if the robot base should be pinned to the static environment.
  field  MFNode      toolSlot        []     # Extend the robot with new nodes at the end of the arm.
]
{
  Robot {
    translation IS translation
    rotation IS rotation
    controller IS controller
    controllerArgs IS controllerArgs
    customData IS customData
    supervisor IS supervisor
    synchronization IS synchronization
    selfCollision IS selfCollision
    children [
      KukaKr1502_base_link_0Mesh {
      }
      HingeJoint {
        jointParameters HingeJointParameters {
          axis 0.000000 0.000000 -1.000000
          anchor 0.000000 0.000000 0.750000
          dampingConstant 0.0
          staticFriction 0.0
        }
        device [
          RotationalMotor {
            name "joint_a1"
            maxVelocity 1.91986217719
            minPosition -3.22885911619
            maxPosition 3.22885911619
            maxTorque 10000
          }
          PositionSensor {
            name "joint_a1_sensor"
          }
        ]
        endPoint Solid {
          translation 0.000000 0.000000 0.750000
          rotation 0.000000 1.000000 0.000000 0.000000
          children [
            KukaKr1502_link_1_0Mesh {
            }
            KukaKr1502_link_1_1Mesh {
            }
            KukaKr1502_link_1_2Mesh {
            }
            KukaKr1502_link_1_3Mesh {
            }
            KukaKr1502_link_1_4Mesh {
            }
            KukaKr1502_link_1_5Mesh {
            }
            KukaKr1502_link_1_6Mesh {
            }
            HingeJoint {
              jointParameters HingeJointParameters {
                axis 0.000000 1.000000 0.000000
                anchor 0.350000 0.000000 0.000000
                dampingConstant 0.0
                staticFriction 0.0
              }
              device [
                RotationalMotor {
                  name "joint_a2"
                  maxVelocity 1.91986217719
                  minPosition -2.54818070791
                  maxTorque 10000
                }
                PositionSensor {
                  name "joint_a2_sensor"
                }
              ]
              endPoint Solid {
                translation 0.350000 0.000000 0.000000
                rotation 0.000000 1.000000 0.000000 0.000000
                children [
                  KukaKr1502_link_2_0Mesh {
                  }
                  HingeJoint {
                    jointParameters HingeJointParameters {
                      axis 0.000000 1.000000 0.000000
                      anchor 1.250000 0.000000 0.000000
                      dampingConstant 0.0
                      staticFriction 0.0
                    }
                    device [
                      RotationalMotor {
                        name "joint_a3"
                        maxVelocity 1.74532925199
                        minPosition -2.07694180987
                        maxPosition 2.70526034059
                        maxTorque 10000
                      }
                      PositionSensor {
                        name "joint_a3_sensor"
                      }
                    ]
                    endPoint Solid {
                      translation 1.250000 0.000000 0.000000
                      rotation 0.000000 1.000000 0.000000 0.000000
                      children [
                        KukaKr1502_link_3_0Mesh {
                        }
                        KukaKr1502_link_3_1Mesh {
                        }
                        KukaKr1502_link_3_2Mesh {
                        }
                        KukaKr1502_link_3_3Mesh {
                        }
                        KukaKr1502_link_3_4Mesh {
                        }
                        KukaKr1502_link_3_5Mesh {
                        }
                        HingeJoint {
                          jointParameters HingeJointParameters {
                            axis -1.000000 0.000000 0.000000
                            anchor 0.000000 0.000000 -0.055000
                            dampingConstant 0.0
                            staticFriction 0.0
                          }
                          device [
                            RotationalMotor {
                              name "joint_a4"
                              maxVelocity 2.96705972839
                              minPosition -6.10865238198
                              maxPosition 6.10865238198
                              maxTorque 10000
                            }
                            PositionSensor {
                              name "joint_a4_sensor"
                            }
                          ]
                          endPoint Solid {
                            translation 0.000000 0.000000 -0.055000
                            rotation 0.000000 1.000000 0.000000 0.000000
                            children [
                              KukaKr1502_link_4_0Mesh {
                              }
                              KukaKr1502_link_4_1Mesh {
                              }
                              KukaKr1502_link_4_2Mesh {
                              }
                              KukaKr1502_link_4_3Mesh {
                              }
                              KukaKr1502_link_4_4Mesh {
                              }
                              HingeJoint {
                                jointParameters HingeJointParameters {
                                  axis 0.000000 1.000000 0.000000
                                  anchor 1.100000 0.000000 0.000000
                                  dampingConstant 0.0
                                  staticFriction 0.0
                                }
                                device [
                                  RotationalMotor {
                                    name "joint_a5"
                                    maxVelocity 2.96705972839
                                    minPosition -2.18166156499
                                    maxPosition 2.18166156499
                                    maxTorque 10000
                                  }
                                  PositionSensor {
                                    name "joint_a5_sensor"
                                  }
                                ]
                                endPoint Solid {
                                  translation 1.100000 0.000000 0.000000
                                  rotation 0.000000 1.000000 0.000000 0.000000
                                  children [
                                    KukaKr1502_link_5_0Mesh {
                                    }
                                    HingeJoint {
                                      jointParameters HingeJointParameters {
                                        axis -1.000000 0.000000 0.000000
                                        anchor 0.230000 0.000000 0.000000
                                        dampingConstant 0.0
                                        staticFriction 0.0
                                      }
                                      device [
                                        RotationalMotor {
                                          name "joint_a6"
                                          maxVelocity 4.15388361975
                                          minPosition -6.10865238198
                                          maxPosition 6.10865238198
                                          maxTorque 10000
                                        }
                                        PositionSensor {
                                          name "joint_a6_sensor"
                                        }
                                      ]
                                      endPoint Solid {
                                        translation 0.230000 0.000000 0.000000
                                        rotation 0.000000 1.000000 0.000000 0.000000
                                        children [
                                          KukaKr1502_link_6_0Mesh {
                                          }
                                          Solid {
                                            translation 0.000000 0.000000 0.000000
                                            rotation 0.000000 1.000000 0.000000 1.570796
                                            children [
                                              Group {
                                                children IS toolSlot
                                              }
                                            ]
                                            name "tool0"
                                          }
                                        ]
                                        name "link_6"
                                        boundingObject Transform {
                                          translation -0.018750 0.000000 0.000178
                                          children [
                                            Box {
                                              size 0.037500 0.197822 0.197643
                                            }
                                          ]
                                        }
                                        physics Physics {
                                          density -1
                                          mass 1.000000
                                          centerOfMass [ 0.000000 0.000000 0.000000 ]
                                        }
                                      }
                                    }
                                  ]
                                  name "link_5"
                                  boundingObject Transform {
                                    translation 0.036250 -0.000408 0.000008
                                    children [
                                      Box {
                                        size 0.312500 0.239796 0.239996
                                      }
                                    ]
                                  }
                                  physics Physics {
                                    density -1
                                    mass 1.000000
                                    centerOfMass [ 0.000000 0.000000 0.000000 ]
                                  }
                                }
                              }
                            ]
                            name "link_4"
                            boundingObject Transform {
                              translation 0.975999 -0.006460 0.000002
                              children [
                                Box {
                                  size 0.457999 0.340919 0.209990
                                }
                              ]
                            }
                            physics Physics {
                              density -1
                              mass 1.000000
                              centerOfMass [ 0.000000 0.000000 0.000000 ]
                            }
                          }
                        }
                      ]
                      name "link_3"
                      boundingObject Transform {
                        translation 0.170900 0.054500 -0.056348
                        children [
                          Box {
                            size 1.152200 0.477000 0.533490
                          }
                        ]
                      }
                      physics Physics {
                        density -1
                        mass 1.000000
                        centerOfMass [ 0.000000 0.000000 0.000000 ]
                      }
                    }
                  }
                ]
                name "link_2"
                boundingObject Transform {
                  translation 0.609123 -0.199000 0.008662
                  children [
                    Box {
                      size 1.662790 0.492000 0.470187
                    }
                  ]
                }
                physics Physics {
                  density -1
                  mass 1.000000
                  centerOfMass [ 0.000000 0.000000 0.000000 ]
                }
              }
            }
          ]
          name "link_1"
          boundingObject Transform {
            translation 0.024820 -0.000023 -0.087009
            children [
              Box {
                size 1.140446 0.919907 0.664001
              }
            ]
          }
          physics Physics {
            density -1
            mass 1.000000
            centerOfMass [ 0.000000 0.000000 0.000000 ]
          }
        }
      }
      Solid {
        translation 0.000000 0.000000 0.000000
        rotation 0.000000 1.000000 0.000000 0.000000
        name "base"
      }
    ]
    name "base_link"
    boundingObject Transform {
      translation -0.094674 0.000000 0.165495
      children [
        Box {
          size 1.189348 0.999675 0.330990
        }
      ]
    }
    %{ if fields.staticBase.value == false then }%
    physics Physics {
      density -1
      mass 1.000000
      centerOfMass [ 0.000000 0.000000 0.000000 ]
    }
    %{ end }%
  }
}
