#VRML_SIM R2020b utf8
# license: Apache License 2.0
# license url: http://www.apache.org/licenses/LICENSE-2.0
# This is a proto file for Webots for the KukaKr10r1100sixx
# Extracted from: model.urdf

PROTO KukaKr10r1100sixx [
  field  SFVec3f     translation     0 0 0
  field  SFRotation  rotation        1 0 0 -1.5708
  field  SFString    controller      "void" # Is `Robot.controller`.
  field  MFString    controllerArgs  []     # Is `Robot.controllerArgs`.
  field  SFString    customData      ""     # Is `Robot.customData`.
  field  SFBool      supervisor      FALSE  # Is `Robot.supervisor`.
  field  SFBool      synchronization TRUE   # Is `Robot.synchronization`.
  field  SFBool      selfCollision   FALSE  # Is `Robot.selfCollision`.
  field  SFBool      staticBase      TRUE   # Defines if the robot base should be pinned to the static environment.
  field  MFNode      toolSlot        []     # Extend the robot with new nodes at the end of the arm.
]
{
  Robot {
    translation IS translation
    rotation IS rotation
    controller IS controller
    controllerArgs IS controllerArgs
    customData IS customData
    supervisor IS supervisor
    synchronization IS synchronization
    selfCollision IS selfCollision
    children [
      KukaKr10r1100sixx_base_linkMesh {
      }
      HingeJoint {
        jointParameters HingeJointParameters {
          axis 0.000000 0.000000 -1.000000
          anchor 0.000000 0.000000 0.400000
          dampingConstant 0.0
          staticFriction 0.0
        }
        device [
          RotationalMotor {
            name "joint_a1"
            maxVelocity 6.28318530718
            minPosition -2.96705972839
            maxPosition 2.96705972839
            maxTorque 10000
          }
          PositionSensor {
            name "joint_a1_sensor"
          }
        ]
        endPoint Solid {
          translation 0.000000 0.000000 0.400000
          rotation 0.000000 1.000000 0.000000 0.000000
          children [
            KukaKr10r1100sixx_link_1Mesh {
            }
            HingeJoint {
              jointParameters HingeJointParameters {
                axis 0.000000 1.000000 0.000000
                anchor 0.025000 0.000000 0.000000
                dampingConstant 0.0
                staticFriction 0.0
              }
              device [
                RotationalMotor {
                  name "joint_a2"
                  maxVelocity 5.23598775598
                  minPosition -3.31612557879
                  maxPosition 0.785398163397
                  maxTorque 10000
                }
                PositionSensor {
                  name "joint_a2_sensor"
                }
              ]
              endPoint Solid {
                translation 0.025000 0.000000 0.000000
                rotation 0.000000 1.000000 0.000000 0.000000
                children [
                  KukaKr10r1100sixx_link_2Mesh {
                  }
                  HingeJoint {
                    jointParameters HingeJointParameters {
                      axis 0.000000 1.000000 0.000000
                      anchor 0.560000 0.000000 0.000000
                      dampingConstant 0.0
                      staticFriction 0.0
                    }
                    device [
                      RotationalMotor {
                        name "joint_a3"
                        maxVelocity 6.28318530718
                        minPosition -2.09439510239
                        maxPosition 2.72271363311
                        maxTorque 10000
                      }
                      PositionSensor {
                        name "joint_a3_sensor"
                      }
                    ]
                    endPoint Solid {
                      translation 0.560000 0.000000 0.000000
                      rotation 0.000000 1.000000 0.000000 0.000000
                      children [
                        KukaKr10r1100sixx_link_3Mesh {
                        }
                        HingeJoint {
                          jointParameters HingeJointParameters {
                            axis -1.000000 0.000000 0.000000
                            anchor 0.000000 0.000000 0.035000
                            dampingConstant 0.0
                            staticFriction 0.0
                          }
                          device [
                            RotationalMotor {
                              name "joint_a4"
                              maxVelocity 6.6497044501
                              minPosition -3.22885911619
                              maxPosition 3.22885911619
                              maxTorque 10000
                            }
                            PositionSensor {
                              name "joint_a4_sensor"
                            }
                          ]
                          endPoint Solid {
                            translation 0.000000 0.000000 0.035000
                            rotation 0.000000 1.000000 0.000000 0.000000
                            children [
                              KukaKr10r1100sixx_link_4Mesh {
                              }
                              HingeJoint {
                                jointParameters HingeJointParameters {
                                  axis 0.000000 1.000000 0.000000
                                  anchor 0.515000 0.000000 0.000000
                                  dampingConstant 0.0
                                  staticFriction 0.0
                                }
                                device [
                                  RotationalMotor {
                                    name "joint_a5"
                                    maxVelocity 6.77187749774
                                    minPosition -2.09439510239
                                    maxPosition 2.09439510239
                                    maxTorque 10000
                                  }
                                  PositionSensor {
                                    name "joint_a5_sensor"
                                  }
                                ]
                                endPoint Solid {
                                  translation 0.515000 0.000000 0.000000
                                  rotation 0.000000 1.000000 0.000000 0.000000
                                  children [
                                    KukaKr10r1100sixx_link_5Mesh {
                                    }
                                    HingeJoint {
                                      jointParameters HingeJointParameters {
                                        axis -1.000000 0.000000 0.000000
                                        anchor 0.080000 0.000000 0.000000
                                        dampingConstant 0.0
                                        staticFriction 0.0
                                      }
                                      device [
                                        RotationalMotor {
                                          name "joint_a6"
                                          maxVelocity 10.7337748998
                                          minPosition -6.10865238198
                                          maxPosition 6.10865238198
                                          maxTorque 10000
                                        }
                                        PositionSensor {
                                          name "joint_a6_sensor"
                                        }
                                      ]
                                      endPoint Solid {
                                        translation 0.080000 0.000000 0.000000
                                        rotation 0.000000 1.000000 0.000000 0.000000
                                        children [
                                          KukaKr10r1100sixx_link_6Mesh {
                                          }
                                          Solid {
                                            translation 0.000000 0.000000 0.000000
                                            rotation 0.000000 1.000000 0.000000 1.570796
                                            children [
                                              Group {
                                                children IS toolSlot
                                              }
                                            ]
                                            name "tool0"
                                          }
                                        ]
                                        name "link_6"
                                        boundingObject Transform {
                                          translation -0.006767 -0.000004 -0.000994
                                          children [
                                            Box {
                                              size 0.014031 0.039986 0.040151
                                            }
                                          ]
                                        }
                                        physics Physics {
                                          density -1
                                          mass 1.000000
                                          centerOfMass [ 0.000000 0.000000 0.000000 ]
                                        }
                                      }
                                    }
                                  ]
                                  name "link_5"
                                  boundingObject Transform {
                                    translation 0.018621 -0.000250 0.000011
                                    children [
                                      Box {
                                        size 0.116628 0.078500 0.079368
                                      }
                                    ]
                                  }
                                  physics Physics {
                                    density -1
                                    mass 1.000000
                                    centerOfMass [ 0.000000 0.000000 0.000000 ]
                                  }
                                }
                              }
                            ]
                            name "link_4"
                            boundingObject Transform {
                              translation 0.332212 -0.000077 0.015890
                              children [
                                Box {
                                  size 0.450423 0.119154 0.142708
                                }
                              ]
                            }
                            physics Physics {
                              density -1
                              mass 1.000000
                              centerOfMass [ 0.000000 0.000000 0.000000 ]
                            }
                          }
                        }
                      ]
                      name "link_3"
                      boundingObject Transform {
                        translation 0.020318 0.000000 0.008034
                        children [
                          Box {
                            size 0.193363 0.135000 0.168932
                          }
                        ]
                      }
                      physics Physics {
                        density -1
                        mass 1.000000
                        centerOfMass [ 0.000000 0.000000 0.000000 ]
                      }
                    }
                  }
                ]
                name "link_2"
                boundingObject Transform {
                  translation 0.279764 -0.004500 0.000001
                  children [
                    Box {
                      size 0.735472 0.249000 0.175976
                    }
                  ]
                }
                physics Physics {
                  density -1
                  mass 1.000000
                  centerOfMass [ 0.000000 0.000000 0.000000 ]
                }
              }
            }
          ]
          name "link_1"
          boundingObject Transform {
            translation 0.011590 -0.000963 -0.048337
            children [
              Box {
                size 0.242821 0.275889 0.269325
              }
            ]
          }
          physics Physics {
            density -1
            mass 1.000000
            centerOfMass [ 0.000000 0.000000 0.000000 ]
          }
        }
      }
      Solid {
        translation 0.000000 0.000000 0.000000
        rotation 0.000000 1.000000 0.000000 0.000000
        name "base"
      }
    ]
    name "base_link"
    boundingObject Transform {
      translation -0.056836 0.000002 0.130400
      children [
        Box {
          size 0.328328 0.214730 0.260800
        }
      ]
    }
    %{ if fields.staticBase.value == false then }%
    physics Physics {
      density -1
      mass 1.000000
      centerOfMass [ 0.000000 0.000000 0.000000 ]
    }
    %{ end }%
  }
}
